{"uuid": "c5f5a1b7-ea8e-4459-8b41-9daba730081f", "children": ["5fae10b2-eee3-4e5e-aace-911b3712009a", "7c6f5502-7302-4fcc-8be3-b7733a584039", "0547a33b-92c9-4cf1-a9b3-64c026ee33f2", "45bed64c-9576-43a2-a0c7-2f16afda2dda"], "befores": [{"name": "xunit_setup_class_fixture_Test_Search_Setting", "status": "broken", "statusDetails": {"message": "selenium.common.exceptions.WebDriverException: Message: An unknown server-side error occurred while processing the command. Original error: Could not find a connected Android device.\n\n", "trace": "  File \"C:\\Users\\Administrator\\AppData\\Roaming\\Python\\Python37\\site-packages\\pluggy\\callers.py\", line 187, in _multicall\n    res = hook_impl.function(*args)\n  File \"C:\\Users\\Administrator\\AppData\\Roaming\\Python\\Python37\\site-packages\\_pytest\\fixtures.py\", line 1126, in pytest_fixture_setup\n    result = call_fixture_func(fixturefunc, request, kwargs)\n  File \"C:\\Users\\Administrator\\AppData\\Roaming\\Python\\Python37\\site-packages\\_pytest\\fixtures.py\", line 925, in call_fixture_func\n    fixture_result = next(generator)\n  File \"C:\\Users\\Administrator\\AppData\\Roaming\\Python\\Python37\\site-packages\\_pytest\\python.py\", line 811, in xunit_setup_class_fixture\n    _call_with_optional_argument(func, self.obj)\n  File \"C:\\Users\\Administrator\\AppData\\Roaming\\Python\\Python37\\site-packages\\_pytest\\python.py\", line 739, in _call_with_optional_argument\n    func(arg)\n  File \"D:\\BaiduNetdiskDownload\\sorttest\\app_auto_script\\scripts\\test_search_setting.py\", line 27, in setup_class\n    self.driver = init_driver()\n  File \"D:\\BaiduNetdiskDownload\\sorttest\\app_auto_script\\Base\\initdriver.py\", line 15, in init_driver\n    driver = webdriver.Remote('http://localhost:4723/wd/hub', desired_caps)\n  File \"c:\\users\\administrator\\appdata\\local\\programs\\python\\python37\\lib\\site-packages\\appium_python_client-0.25-py3.7.egg\\appium\\webdriver\\webdriver.py\", line 36, in __init__\n    super(WebDriver, self).__init__(command_executor, desired_capabilities, browser_profile, proxy, keep_alive)\n  File \"c:\\users\\administrator\\appdata\\local\\programs\\python\\python37\\lib\\site-packages\\selenium\\webdriver\\remote\\webdriver.py\", line 87, in __init__\n    self.start_session(desired_capabilities, browser_profile)\n  File \"c:\\users\\administrator\\appdata\\local\\programs\\python\\python37\\lib\\site-packages\\selenium\\webdriver\\remote\\webdriver.py\", line 141, in start_session\n    'desiredCapabilities': desired_capabilities,\n  File \"c:\\users\\administrator\\appdata\\local\\programs\\python\\python37\\lib\\site-packages\\selenium\\webdriver\\remote\\webdriver.py\", line 201, in execute\n    self.error_handler.check_response(response)\n  File \"c:\\users\\administrator\\appdata\\local\\programs\\python\\python37\\lib\\site-packages\\selenium\\webdriver\\remote\\errorhandler.py\", line 181, in check_response\n    raise exception_class(message, screen, stacktrace)\n"}, "start": 1610548100514, "stop": 1610548143275}], "start": 1610548100514, "stop": 1610548143655}